[2023-01-17T22:43:57.846+0000] {taskinstance.py:1087} INFO - Dependencies all met for <TaskInstance: accidents_data_etl_pipeline.cleanning_dataset manual__2023-01-17T22:37:39.465011+00:00 [queued]>
[2023-01-17T22:43:57.868+0000] {taskinstance.py:1087} INFO - Dependencies all met for <TaskInstance: accidents_data_etl_pipeline.cleanning_dataset manual__2023-01-17T22:37:39.465011+00:00 [queued]>
[2023-01-17T22:43:57.869+0000] {taskinstance.py:1283} INFO - 
--------------------------------------------------------------------------------
[2023-01-17T22:43:57.870+0000] {taskinstance.py:1284} INFO - Starting attempt 2 of 2
[2023-01-17T22:43:57.871+0000] {taskinstance.py:1285} INFO - 
--------------------------------------------------------------------------------
[2023-01-17T22:43:57.896+0000] {taskinstance.py:1304} INFO - Executing <Task(PythonOperator): cleanning_dataset> on 2023-01-17 22:37:39.465011+00:00
[2023-01-17T22:43:57.916+0000] {standard_task_runner.py:55} INFO - Started process 9590 to run task
[2023-01-17T22:43:57.922+0000] {standard_task_runner.py:82} INFO - Running: ['***', 'tasks', 'run', 'accidents_data_etl_pipeline', 'cleanning_dataset', 'manual__2023-01-17T22:37:39.465011+00:00', '--job-id', '47', '--raw', '--subdir', 'DAGS_FOLDER/etl.py', '--cfg-path', '/tmp/tmpx5r6lwpc']
[2023-01-17T22:43:57.925+0000] {standard_task_runner.py:83} INFO - Job 47: Subtask cleanning_dataset
[2023-01-17T22:43:58.033+0000] {task_command.py:389} INFO - Running <TaskInstance: accidents_data_etl_pipeline.cleanning_dataset manual__2023-01-17T22:37:39.465011+00:00 [running]> on host 7fc7752d3cb4
[2023-01-17T22:43:58.161+0000] {taskinstance.py:1513} INFO - Exporting the following env vars:
AIRFLOW_CTX_DAG_OWNER=***
AIRFLOW_CTX_DAG_ID=accidents_data_etl_pipeline
AIRFLOW_CTX_TASK_ID=cleanning_dataset
AIRFLOW_CTX_EXECUTION_DATE=2023-01-17T22:37:39.465011+00:00
AIRFLOW_CTX_TRY_NUMBER=2
AIRFLOW_CTX_DAG_RUN_ID=manual__2023-01-17T22:37:39.465011+00:00
[2023-01-17T22:44:09.498+0000] {logging_mixin.py:137} WARNING - /home/***/.local/lib/python3.7/site-packages/***/operators/python.py:192 DtypeWarning: Columns (10,28,29) have mixed types.Specify dtype option on import or set low_memory=False.
[2023-01-17T22:44:17.793+0000] {taskinstance.py:1772} ERROR - Task failed with exception
Traceback (most recent call last):
  File "/home/airflow/.local/lib/python3.7/site-packages/airflow/operators/python.py", line 175, in execute
    return_value = self.execute_callable()
  File "/home/airflow/.local/lib/python3.7/site-packages/airflow/operators/python.py", line 192, in execute_callable
    return self.python_callable(*self.op_args, **self.op_kwargs)
  File "/opt/airflow/dags/etl.py", line 100, in data_clean
    df['age_of_driver'] = df['age_of_driver'].apply(impute_age_outliers(upper))
TypeError: impute_age_outliers() missing 1 required positional argument: 'upper'
[2023-01-17T22:44:17.826+0000] {taskinstance.py:1327} INFO - Marking task as FAILED. dag_id=accidents_data_etl_pipeline, task_id=cleanning_dataset, execution_date=20230117T223739, start_date=20230117T224357, end_date=20230117T224417
[2023-01-17T22:44:17.866+0000] {standard_task_runner.py:105} ERROR - Failed to execute job 47 for task cleanning_dataset (impute_age_outliers() missing 1 required positional argument: 'upper'; 9590)
[2023-01-17T22:44:17.940+0000] {local_task_job.py:159} INFO - Task exited with return code 1
[2023-01-17T22:44:18.027+0000] {taskinstance.py:2582} INFO - 0 downstream tasks scheduled from follow-on schedule check
