[2023-01-17T22:38:33.995+0000] {taskinstance.py:1087} INFO - Dependencies all met for <TaskInstance: accidents_data_etl_pipeline.cleanning_dataset manual__2023-01-17T22:37:39.465011+00:00 [queued]>
[2023-01-17T22:38:34.014+0000] {taskinstance.py:1087} INFO - Dependencies all met for <TaskInstance: accidents_data_etl_pipeline.cleanning_dataset manual__2023-01-17T22:37:39.465011+00:00 [queued]>
[2023-01-17T22:38:34.014+0000] {taskinstance.py:1283} INFO - 
--------------------------------------------------------------------------------
[2023-01-17T22:38:34.015+0000] {taskinstance.py:1284} INFO - Starting attempt 1 of 2
[2023-01-17T22:38:34.016+0000] {taskinstance.py:1285} INFO - 
--------------------------------------------------------------------------------
[2023-01-17T22:38:34.046+0000] {taskinstance.py:1304} INFO - Executing <Task(PythonOperator): cleanning_dataset> on 2023-01-17 22:37:39.465011+00:00
[2023-01-17T22:38:34.059+0000] {standard_task_runner.py:55} INFO - Started process 9300 to run task
[2023-01-17T22:38:34.066+0000] {standard_task_runner.py:82} INFO - Running: ['***', 'tasks', 'run', 'accidents_data_etl_pipeline', 'cleanning_dataset', 'manual__2023-01-17T22:37:39.465011+00:00', '--job-id', '43', '--raw', '--subdir', 'DAGS_FOLDER/etl.py', '--cfg-path', '/tmp/tmpmmo_ygnl']
[2023-01-17T22:38:34.069+0000] {standard_task_runner.py:83} INFO - Job 43: Subtask cleanning_dataset
[2023-01-17T22:38:34.231+0000] {task_command.py:389} INFO - Running <TaskInstance: accidents_data_etl_pipeline.cleanning_dataset manual__2023-01-17T22:37:39.465011+00:00 [running]> on host 7fc7752d3cb4
[2023-01-17T22:38:34.527+0000] {taskinstance.py:1513} INFO - Exporting the following env vars:
AIRFLOW_CTX_DAG_OWNER=***
AIRFLOW_CTX_DAG_ID=accidents_data_etl_pipeline
AIRFLOW_CTX_TASK_ID=cleanning_dataset
AIRFLOW_CTX_EXECUTION_DATE=2023-01-17T22:37:39.465011+00:00
AIRFLOW_CTX_TRY_NUMBER=1
AIRFLOW_CTX_DAG_RUN_ID=manual__2023-01-17T22:37:39.465011+00:00
[2023-01-17T22:38:46.561+0000] {logging_mixin.py:137} WARNING - /home/***/.local/lib/python3.7/site-packages/***/operators/python.py:192 DtypeWarning: Columns (10,28,29) have mixed types.Specify dtype option on import or set low_memory=False.
[2023-01-17T22:38:53.506+0000] {taskinstance.py:1772} ERROR - Task failed with exception
Traceback (most recent call last):
  File "/home/airflow/.local/lib/python3.7/site-packages/airflow/operators/python.py", line 175, in execute
    return_value = self.execute_callable()
  File "/home/airflow/.local/lib/python3.7/site-packages/airflow/operators/python.py", line 192, in execute_callable
    return self.python_callable(*self.op_args, **self.op_kwargs)
  File "/opt/airflow/dags/etl.py", line 100, in data_clean
    df['age_of_driver'] = df['age_of_driver'].apply(impute_age_outliers)
  File "/home/airflow/.local/lib/python3.7/site-packages/pandas/core/series.py", line 4357, in apply
    return SeriesApply(self, func, convert_dtype, args, kwargs).apply()
  File "/home/airflow/.local/lib/python3.7/site-packages/pandas/core/apply.py", line 1043, in apply
    return self.apply_standard()
  File "/home/airflow/.local/lib/python3.7/site-packages/pandas/core/apply.py", line 1101, in apply_standard
    convert=self.convert_dtype,
  File "pandas/_libs/lib.pyx", line 2859, in pandas._libs.lib.map_infer
  File "/opt/airflow/dags/etl.py", line 180, in impute_age_outliers
    if x > upper:
NameError: name 'upper' is not defined
[2023-01-17T22:38:53.532+0000] {taskinstance.py:1327} INFO - Marking task as UP_FOR_RETRY. dag_id=accidents_data_etl_pipeline, task_id=cleanning_dataset, execution_date=20230117T223739, start_date=20230117T223833, end_date=20230117T223853
[2023-01-17T22:38:53.559+0000] {standard_task_runner.py:105} ERROR - Failed to execute job 43 for task cleanning_dataset (name 'upper' is not defined; 9300)
[2023-01-17T22:38:53.618+0000] {local_task_job.py:159} INFO - Task exited with return code 1
[2023-01-17T22:38:53.656+0000] {taskinstance.py:2582} INFO - 0 downstream tasks scheduled from follow-on schedule check
