[2023-01-17T22:49:15.725+0000] {taskinstance.py:1087} INFO - Dependencies all met for <TaskInstance: accidents_data_etl_pipeline.cleanning_dataset manual__2023-01-17T22:48:12.753375+00:00 [queued]>
[2023-01-17T22:49:15.754+0000] {taskinstance.py:1087} INFO - Dependencies all met for <TaskInstance: accidents_data_etl_pipeline.cleanning_dataset manual__2023-01-17T22:48:12.753375+00:00 [queued]>
[2023-01-17T22:49:15.757+0000] {taskinstance.py:1283} INFO - 
--------------------------------------------------------------------------------
[2023-01-17T22:49:15.759+0000] {taskinstance.py:1284} INFO - Starting attempt 1 of 2
[2023-01-17T22:49:15.760+0000] {taskinstance.py:1285} INFO - 
--------------------------------------------------------------------------------
[2023-01-17T22:49:15.810+0000] {taskinstance.py:1304} INFO - Executing <Task(PythonOperator): cleanning_dataset> on 2023-01-17 22:48:12.753375+00:00
[2023-01-17T22:49:15.826+0000] {standard_task_runner.py:55} INFO - Started process 9861 to run task
[2023-01-17T22:49:15.833+0000] {standard_task_runner.py:82} INFO - Running: ['***', 'tasks', 'run', 'accidents_data_etl_pipeline', 'cleanning_dataset', 'manual__2023-01-17T22:48:12.753375+00:00', '--job-id', '51', '--raw', '--subdir', 'DAGS_FOLDER/etl.py', '--cfg-path', '/tmp/tmpz2qog4n8']
[2023-01-17T22:49:15.847+0000] {standard_task_runner.py:83} INFO - Job 51: Subtask cleanning_dataset
[2023-01-17T22:49:16.147+0000] {task_command.py:389} INFO - Running <TaskInstance: accidents_data_etl_pipeline.cleanning_dataset manual__2023-01-17T22:48:12.753375+00:00 [running]> on host 7fc7752d3cb4
[2023-01-17T22:49:16.419+0000] {taskinstance.py:1513} INFO - Exporting the following env vars:
AIRFLOW_CTX_DAG_OWNER=***
AIRFLOW_CTX_DAG_ID=accidents_data_etl_pipeline
AIRFLOW_CTX_TASK_ID=cleanning_dataset
AIRFLOW_CTX_EXECUTION_DATE=2023-01-17T22:48:12.753375+00:00
AIRFLOW_CTX_TRY_NUMBER=1
AIRFLOW_CTX_DAG_RUN_ID=manual__2023-01-17T22:48:12.753375+00:00
[2023-01-17T22:49:25.309+0000] {logging_mixin.py:137} WARNING - /home/***/.local/lib/python3.7/site-packages/***/operators/python.py:192 DtypeWarning: Columns (10,28,29) have mixed types.Specify dtype option on import or set low_memory=False.
[2023-01-17T22:49:32.280+0000] {taskinstance.py:1772} ERROR - Task failed with exception
Traceback (most recent call last):
  File "/home/airflow/.local/lib/python3.7/site-packages/airflow/operators/python.py", line 175, in execute
    return_value = self.execute_callable()
  File "/home/airflow/.local/lib/python3.7/site-packages/airflow/operators/python.py", line 192, in execute_callable
    return self.python_callable(*self.op_args, **self.op_kwargs)
  File "/opt/airflow/dags/etl.py", line 100, in data_clean
    df['age_of_driver'] = df['age_of_driver'].apply(impute_age_outliers(upper))
TypeError: impute_age_outliers() missing 1 required positional argument: 'upper'
[2023-01-17T22:49:32.305+0000] {taskinstance.py:1327} INFO - Marking task as UP_FOR_RETRY. dag_id=accidents_data_etl_pipeline, task_id=cleanning_dataset, execution_date=20230117T224812, start_date=20230117T224915, end_date=20230117T224932
[2023-01-17T22:49:32.335+0000] {standard_task_runner.py:105} ERROR - Failed to execute job 51 for task cleanning_dataset (impute_age_outliers() missing 1 required positional argument: 'upper'; 9861)
[2023-01-17T22:49:32.370+0000] {local_task_job.py:159} INFO - Task exited with return code 1
[2023-01-17T22:49:32.455+0000] {taskinstance.py:2582} INFO - 0 downstream tasks scheduled from follow-on schedule check
